<?xml version="1.0"?>
<robot name="manipulator" xmlns:xacro="http://www.ros.org/wiki/xacro">
    <xacro:property name="params" value="${load_yaml('../urdf.yaml')}"/>
    <xacro:property name="l_width" value="0.1"/>
 
    <material name="white"> 
        <color rgba="1 1 1 1"/>
    </material>

    <material name="blue">
        <color rgba="0 0.1 0.7 1"/>
    </material>

    <link name="base_link">
        <visual>
            <geometry>
                <cylinder length="0.1" radius="0.3"/>
            </geometry>
            <origin xyz="0 0 -0.05"/>
            <material name="white"/>
        </visual>
    </link>

 <link name="link_1">
        <visual>
            <geometry>
                <cylinder length="${params['s1']['l_len']}" radius="${l_width}"/>
            </geometry>
            <origin xyz="${params['s1']['l_xyz']}" rpy="${params['s1']['l_rpy']}"/>
            <material name="white"/>
        </visual>
    </link>

    <link name="link_2">
        <visual>
            <geometry>
                <cylinder length="${params['s2']['l_len']}" radius="${l_width}"/>
            </geometry>
            <origin xyz="${params['s2']['l_xyz']}" rpy="${params['s2']['l_rpy']}"/>
            <material name="white"/>
        </visual>
    </link>

    <link name="link_3">
        <visual>
            <geometry>
                <cylinder length="${params['s3']['l_len']}" radius="${l_width}"/>
            </geometry>
            <origin xyz="${params['s3']['l_xyz']}" rpy="${params['s3']['l_rpy']}"/>
            <material name="white"/>
        </visual>
    </link>

    <link name="hand">
        <visual>
            <geometry>
                <mesh filename="package://lab2/hand.obj" scale="0.05 0.05 0.1"/>
            </geometry>
            <origin xyz="0 0 0" rpy="-0 0 3.14"/>
            <material name="blue"/>
        </visual>
    </link>        

    <joint name="base_to_link1" type="prismatic">
        <parent link="base_link"/>
        <child link="link_1"/>
        <origin xyz="${params['s1']['j_xyz']}" rpy="${params['s1']['j_rpy']}"/>
        <axis xyz="0 0 1"/>
        <limit effort="1000.0" lower="-1" upper="0" velocity="1"/>
    </joint>

    <joint name="link1_to_link2" type="prismatic">
        <parent link="link_1"/>
        <child link="link_2"/>
        <origin xyz="${params['s2']['j_xyz']}" rpy="${params['s2']['j_rpy']}"/>
        <axis xyz="0 0 1"/>
        <limit effort="1000.0" lower="-1" upper="0" velocity="1"/>
    </joint>

    <joint name="link2_to_link3" type="prismatic">
        <parent link="link_2"/>
        <child link="link_3"/>
        <origin xyz="${params['s3']['j_xyz']}" rpy="${params['s3']['j_rpy']}"/>
        <limit effort="1000.0" lower="-1" upper="0" velocity="1"/>
        <axis xyz="0 0 1"/>
    </joint>

    <joint name="link3_to_hand" type="fixed">
        <parent link="link_3"/>
        <child link="hand"/>
        <origin xyz="0 0 0" rpy="0 0 0"/>
    </joint>

</robot>
